Workbook

Sheet Model
A1: PACT - how a subclass bonus-spell bundle is priced
A3: Engine rules version (js/engine-data.js) | B3: v0.347
A5: READ THIS FIRST - is the origin discount applied twice?
A6: No. A bundle is charged with ONE lookup: engine.js does `_isO ? bundle.origin : bundle.cross`. It
A7: picks one of two stored numbers and never subtracts a discount from either, so there is no second
A8: application to be had. The discount is applied once, when the stored `origin` figure was derived -
A9: and the 'Per-spell working' sheet reproduces that derivation from the real spell lists.
A11: The direct check is the ORIGIN GAP (cross - origin) on the Bundles sheet. If the discount were being
A12: applied twice, the engine's gap would exceed the model's gap. On all 21 bundles it does not - column
A13: N reads 'applied exactly once' for every one.
A15: What DOES look wrong side by side, and isn't: the guide's ability tables head column 3 'Sticker
A16: (Origin)'. For an ordinary class feature the sticker is already reduced - sticker = cross - tier. A
A17: bundle has no tier, so nothing is subtracted and the sticker equals the full cross price. Both mean
A18: 'what a non-origin member of that class pays'; they are just reached differently. See 'Price paths'.
A20: Inputs (blue = hardcoded here, green = read from the engine)
A21: Origin discount, AP per spell | B21: 1
A22: Floor - no spell can cost less than this | B22: 1
A23: Cantrip granted by a bundle, flat AP each (no discount) | B23: 4
A24: Grants unlocking above this character level ride free | B24: 5
A26: AP per spell known, by spell level (DATA.knownUnit)
A27: 1 | B27: 1
A28: 2 | B28: 1
A29: 3 | B29: 2
A30: 4 | B30: 2
A31: 5 | B31: 3
A32: 6 | B32: 3
A33: 7 | B33: 4
A34: 8 | B34: 4
A35: 9 | B35: 5
A37: Where the spell lists come from
A38: DATA.spellGrants.subclassSpells - the engine's own index of every 2024 ability that grants spells,
A39: with each spell's level and the character level its grant unlocks at. Nothing here is reconstructed.
A40: This reproduces 20 of the 21 stored prices exactly; Circle of the Sea is the single miss (charged
A41: 11/9 where its seven paid grants total 12/10 - the same shape as Aberrant Sorcery, charged 12/10).

Sheet Per-spell working
A1: Key | B1: Class | C1: Subclass | D1: Spell | E1: Spell level (0 = cantrip) | F1: Unlocks at char level | G1: Paid or free | H1: Cross AP | I1: Origin AP (-1, floored at 1) | J1: Discount saved
A2: Cleric|Life Domain | B2: Cleric | C2: Life Domain | D2: Aid | E2: 2 | F2: 3 | G2: =IF(F2<=Model!$B$24,"PAID","free with bundle") | H2: =VLOOKUP(E2,Model!$A$27:$B$35,2,FALSE) | I2: =MAX(Model!$B$22,H2-Model!$B$21) | J2: =H2-I2
A3: Cleric|Life Domain | B3: Cleric | C3: Life Domain | D3: Bless | E3: 1 | F3: 3 | G3: =IF(F3<=Model!$B$24,"PAID","free with bundle") | H3: =VLOOKUP(E3,Model!$A$27:$B$35,2,FALSE) | I3: =MAX(Model!$B$22,H3-Model!$B$21) | J3: =H3-I3
A4: Cleric|Life Domain | B4: Cleric | C4: Life Domain | D4: Cure Wounds | E4: 1 | F4: 3 | G4: =IF(F4<=Model!$B$24,"PAID","free with bundle") | H4: =VLOOKUP(E4,Model!$A$27:$B$35,2,FALSE) | I4: =MAX(Model!$B$22,H4-Model!$B$21) | J4: =H4-I4
A5: Cleric|Life Domain | B5: Cleric | C5: Life Domain | D5: Lesser Restoration | E5: 2 | F5: 3 | G5: =IF(F5<=Model!$B$24,"PAID","free with bundle") | H5: =VLOOKUP(E5,Model!$A$27:$B$35,2,FALSE) | I5: =MAX(Model!$B$22,H5-Model!$B$21) | J5: =H5-I5
A6: Cleric|Life Domain | B6: Cleric | C6: Life Domain | D6: Mass Healing Word | E6: 3 | F6: 5 | G6: =IF(F6<=Model!$B$24,"PAID","free with bundle") | H6: =VLOOKUP(E6,Model!$A$27:$B$35,2,FALSE) | I6: =MAX(Model!$B$22,H6-Model!$B$21) | J6: =H6-I6
A7: Cleric|Life Domain | B7: Cleric | C7: Life Domain | D7: Revivify | E7: 3 | F7: 5 | G7: =IF(F7<=Model!$B$24,"PAID","free with bundle") | H7: =VLOOKUP(E7,Model!$A$27:$B$35,2,FALSE) | I7: =MAX(Model!$B$22,H7-Model!$B$21) | J7: =H7-I7
A8: Cleric|Life Domain | B8: Cleric | C8: Life Domain | D8: Aura of Life | E8: 4 | F8: 7 | G8: =IF(F8<=Model!$B$24,"PAID","free with bundle") | H8: 0 | I8: 0 | J8: =H8-I8
A9: Cleric|Life Domain | B9: Cleric | C9: Life Domain | D9: Death Ward | E9: 4 | F9: 7 | G9: =IF(F9<=Model!$B$24,"PAID","free with bundle") | H9: 0 | I9: 0 | J9: =H9-I9
A10: Cleric|Life Domain | B10: Cleric | C10: Life Domain | D10: Greater Restoration | E10: 5 | F10: 9 | G10: =IF(F10<=Model!$B$24,"PAID","free with bundle") | H10: 0 | I10: 0 | J10: =H10-I10
A11: Cleric|Life Domain | B11: Cleric | C11: Life Domain | D11: Mass Cure Wounds | E11: 5 | F11: 9 | G11: =IF(F11<=Model!$B$24,"PAID","free with bundle") | H11: 0 | I11: 0 | J11: =H11-I11
A12: Cleric|Light Domain | B12: Cleric | C12: Light Domain | D12: Burning Hands | E12: 1 | F12: 3 | G12: =IF(F12<=Model!$B$24,"PAID","free with bundle") | H12: =VLOOKUP(E12,Model!$A$27:$B$35,2,FALSE) | I12: =MAX(Model!$B$22,H12-Model!$B$21) | J12: =H12-I12
A13: Cleric|Light Domain | B13: Cleric | C13: Light Domain | D13: Faerie Fire | E13: 1 | F13: 3 | G13: =IF(F13<=Model!$B$24,"PAID","free with bundle") | H13: =VLOOKUP(E13,Model!$A$27:$B$35,2,FALSE) | I13: =MAX(Model!$B$22,H13-Model!$B$21) | J13: =H13-I13
A14: Cleric|Light Domain | B14: Cleric | C14: Light Domain | D14: Scorching Ray | E14: 2 | F14: 3 | G14: =IF(F14<=Model!$B$24,"PAID","free with bundle") | H14: =VLOOKUP(E14,Model!$A$27:$B$35,2,FALSE) | I14: =MAX(Model!$B$22,H14-Model!$B$21) | J14: =H14-I14
A15: Cleric|Light Domain | B15: Cleric | C15: Light Domain | D15: See Invisibility | E15: 2 | F15: 3 | G15: =IF(F15<=Model!$B$24,"PAID","free with bundle") | H15: =VLOOKUP(E15,Model!$A$27:$B$35,2,FALSE) | I15: =MAX(Model!$B$22,H15-Model!$B$21) | J15: =H15-I15
A16: Cleric|Light Domain | B16: Cleric | C16: Light Domain | D16: Daylight | E16: 3 | F16: 5 | G16: =IF(F16<=Model!$B$24,"PAID","free with bundle") | H16: =VLOOKUP(E16,Model!$A$27:$B$35,2,FALSE) | I16: =MAX(Model!$B$22,H16-Model!$B$21) | J16: =H16-I16
A17: Cleric|Light Domain | B17: Cleric | C17: Light Domain | D17: Fireball | E17: 3 | F17: 5 | G17: =IF(F17<=Model!$B$24,"PAID","free with bundle") | H17: =VLOOKUP(E17,Model!$A$27:$B$35,2,FALSE) | I17: =MAX(Model!$B$22,H17-Model!$B$21) | J17: =H17-I17
A18: Cleric|Light Domain | B18: Cleric | C18: Light Domain | D18: Arcane Eye | E18: 4 | F18: 7 | G18: =IF(F18<=Model!$B$24,"PAID","free with bundle") | H18: 0 | I18: 0 | J18: =H18-I18
A19: Cleric|Light Domain | B19: Cleric | C19: Light Domain | D19: Wall of Fire | E19: 4 | F19: 7 | G19: =IF(F19<=Model!$B$24,"PAID","free with bundle") | H19: 0 | I19: 0 | J19: =H19-I19
A20: Cleric|Light Domain | B20: Cleric | C20: Light Domain | D20: Flame Strike | E20: 5 | F20: 9 | G20: =IF(F20<=Model!$B$24,"PAID","free with bundle") | H20: 0 | I20: 0 | J20: =H20-I20
A21: Cleric|Light Domain | B21: Cleric | C21: Light Domain | D21: Scrying | E21: 5 | F21: 9 | G21: =IF(F21<=Model!$B$24,"PAID","free with bundle") | H21: 0 | I21: 0 | J21: =H21-I21
A22: Cleric|Trickery Domain | B22: Cleric | C22: Trickery Domain | D22: Charm Person | E22: 1 | F22: 3 | G22: =IF(F22<=Model!$B$24,"PAID","free with bundle") | H22: =VLOOKUP(E22,Model!$A$27:$B$35,2,FALSE) | I22: =MAX(Model!$B$22,H22-Model!$B$21) | J22: =H22-I22
A23: Cleric|Trickery Domain | B23: Cleric | C23: Trickery Domain | D23: Disguise Self | E23: 1 | F23: 3 | G23: =IF(F23<=Model!$B$24,"PAID","free with bundle") | H23: =VLOOKUP(E23,Model!$A$27:$B$35,2,FALSE) | I23: =MAX(Model!$B$22,H23-Model!$B$21) | J23: =H23-I23
A24: Cleric|Trickery Domain | B24: Cleric | C24: Trickery Domain | D24: Invisibility | E24: 2 | F24: 3 | G24: =IF(F24<=Model!$B$24,"PAID","free with bundle") | H24: =VLOOKUP(E24,Model!$A$27:$B$35,2,FALSE) | I24: =MAX(Model!$B$22,H24-Model!$B$21) | J24: =H24-I24
A25: Cleric|Trickery Domain | B25: Cleric | C25: Trickery Domain | D25: Pass without Trace | E25: 2 | F25: 3 | G25: =IF(F25<=Model!$B$24,"PAID","free with bundle") | H25: =VLOOKUP(E25,Model!$A$27:$B$35,2,FALSE) | I25: =MAX(Model!$B$22,H25-Model!$B$21) | J25: =H25-I25
A26: Cleric|Trickery Domain | B26: Cleric | C26: Trickery Domain | D26: Hypnotic Pattern | E26: 3 | F26: 5 | G26: =IF(F26<=Model!$B$24,"PAID","free with bundle") | H26: =VLOOKUP(E26,Model!$A$27:$B$35,2,FALSE) | I26: =MAX(Model!$B$22,H26-Model!$B$21) | J26: =H26-I26
A27: Cleric|Trickery Domain | B27: Cleric | C27: Trickery Domain | D27: Nondetection | E27: 3 | F27: 5 | G27: =IF(F27<=Model!$B$24,"PAID","free with bundle") | H27: =VLOOKUP(E27,Model!$A$27:$B$35,2,FALSE) | I27: =MAX(Model!$B$22,H27-Model!$B$21) | J27: =H27-I27
A28: Cleric|Trickery Domain | B28: Cleric | C28: Trickery Domain | D28: Confusion | E28: 4 | F28: 7 | G28: =IF(F28<=Model!$B$24,"PAID","free with bundle") | H28: 0 | I28: 0 | J28: =H28-I28
A29: Cleric|Trickery Domain | B29: Cleric | C29: Trickery Domain | D29: Dimension Door | E29: 4 | F29: 7 | G29: =IF(F29<=Model!$B$24,"PAID","free with bundle") | H29: 0 | I29: 0 | J29: =H29-I29
A30: Cleric|Trickery Domain | B30: Cleric | C30: Trickery Domain | D30: Dominate Person | E30: 5 | F30: 9 | G30: =IF(F30<=Model!$B$24,"PAID","free with bundle") | H30: 0 | I30: 0 | J30: =H30-I30
A31: Cleric|Trickery Domain | B31: Cleric | C31: Trickery Domain | D31: Modify Memory | E31: 5 | F31: 9 | G31: =IF(F31<=Model!$B$24,"PAID","free with bundle") | H31: 0 | I31: 0 | J31: =H31-I31
A32: Cleric|War Domain | B32: Cleric | C32: War Domain | D32: Guiding Bolt | E32: 1 | F32: 3 | G32: =IF(F32<=Model!$B$24,"PAID","free with bundle") | H32: =VLOOKUP(E32,Model!$A$27:$B$35,2,FALSE) | I32: =MAX(Model!$B$22,H32-Model!$B$21) | J32: =H32-I32
A33: Cleric|War Domain | B33: Cleric | C33: War Domain | D33: Shield of Faith | E33: 1 | F33: 3 | G33: =IF(F33<=Model!$B$24,"PAID","free with bundle") | H33: =VLOOKUP(E33,Model!$A$27:$B$35,2,FALSE) | I33: =MAX(Model!$B$22,H33-Model!$B$21) | J33: =H33-I33
A34: Cleric|War Domain | B34: Cleric | C34: War Domain | D34: Magic Weapon | E34: 2 | F34: 3 | G34: =IF(F34<=Model!$B$24,"PAID","free with bundle") | H34: =VLOOKUP(E34,Model!$A$27:$B$35,2,FALSE) | I34: =MAX(Model!$B$22,H34-Model!$B$21) | J34: =H34-I34
A35: Cleric|War Domain | B35: Cleric | C35: War Domain | D35: Spiritual Weapon | E35: 2 | F35: 3 | G35: =IF(F35<=Model!$B$24,"PAID","free with bundle") | H35: =VLOOKUP(E35,Model!$A$27:$B$35,2,FALSE) | I35: =MAX(Model!$B$22,H35-Model!$B$21) | J35: =H35-I35
A36: Cleric|War Domain | B36: Cleric | C36: War Domain | D36: Crusader's Mantle | E36: 3 | F36: 5 | G36: =IF(F36<=Model!$B$24,"PAID","free with bundle") | H36: =VLOOKUP(E36,Model!$A$27:$B$35,2,FALSE) | I36: =MAX(Model!$B$22,H36-Model!$B$21) | J36: =H36-I36
A37: Cleric|War Domain | B37: Cleric | C37: War Domain | D37: Spirit Guardians | E37: 3 | F37: 5 | G37: =IF(F37<=Model!$B$24,"PAID","free with bundle") | H37: =VLOOKUP(E37,Model!$A$27:$B$35,2,FALSE) | I37: =MAX(Model!$B$22,H37-Model!$B$21) | J37: =H37-I37
A38: Cleric|War Domain | B38: Cleric | C38: War Domain | D38: Fire Shield | E38: 4 | F38: 7 | G38: =IF(F38<=Model!$B$24,"PAID","free with bundle") | H38: 0 | I38: 0 | J38: =H38-I38
A39: Cleric|War Domain | B39: Cleric | C39: War Domain | D39: Freedom of Movement | E39: 4 | F39: 7 | G39: =IF(F39<=Model!$B$24,"PAID","free with bundle") | H39: 0 | I39: 0 | J39: =H39-I39
A40: Cleric|War Domain | B40: Cleric | C40: War Domain | D40: Hold Monster | E40: 5 | F40: 9 | G40: =IF(F40<=Model!$B$24,"PAID","free with bundle") | H40: 0 | I40: 0 | J40: =H40-I40
...

Sheet Bundles
A1: Class | B1: Subclass | C1: Paid spells | D1: Free spells | E1: Cross AP derived | F1: Origin AP derived | G1: Cross AP ENGINE | H1: Origin AP ENGINE | I1: Cross diff | J1: Origin diff | K1: Origin gap derived | L1: Origin gap ENGINE | M1: Is the discount applied twice? | N1: Derivation reproduces engine?
A2: Cleric | B2: Life Domain | C2: 6 | D2: 4 | E2: =SUMIFS('Per-spell working'!$H$2:$H$190,'Per-spell working'!$A$2:$A$190,"Cleric|Life Domain",'Per-spell working'!$G$2:$G$190,"PAID") | F2: =SUMIFS('Per-spell working'!$I$2:$I$190,'Per-spell working'!$A$2:$A$190,"Cleric|Life Domain",'Per-spell working'!$G$2:$G$190,"PAID") | G2: 8 | H2: 6 | I2: =G2-E2 | J2: =H2-F2 | K2: =E2-F2 | L2: =G2-H2 | M2: =IF(L2>K2,"YES - engine gap exceeds model",IF(L2=K2,"no - applied exactly once","no - applied LESS than once")) | N2: =IF(AND(I2=0,J2=0),"yes","NO")
A3: Cleric | B3: Light Domain | C3: 6 | D3: 4 | E3: =SUMIFS('Per-spell working'!$H$2:$H$190,'Per-spell working'!$A$2:$A$190,"Cleric|Light Domain",'Per-spell working'!$G$2:$G$190,"PAID") | F3: =SUMIFS('Per-spell working'!$I$2:$I$190,'Per-spell working'!$A$2:$A$190,"Cleric|Light Domain",'Per-spell working'!$G$2:$G$190,"PAID") | G3: 8 | H3: 6 | I3: =G3-E3 | J3: =H3-F3 | K3: =E3-F3 | L3: =G3-H3 | M3: =IF(L3>K3,"YES - engine gap exceeds model",IF(L3=K3,"no - applied exactly once","no - applied LESS than once")) | N3: =IF(AND(I3=0,J3=0),"yes","NO")
A4: Cleric | B4: Trickery Domain | C4: 6 | D4: 4 | E4: =SUMIFS('Per-spell working'!$H$2:$H$190,'Per-spell working'!$A$2:$A$190,"Cleric|Trickery Domain",'Per-spell working'!$G$2:$G$190,"PAID") | F4: =SUMIFS('Per-spell working'!$I$2:$I$190,'Per-spell working'!$A$2:$A$190,"Cleric|Trickery Domain",'Per-spell working'!$G$2:$G$190,"PAID") | G4: 8 | H4: 6 | I4: =G4-E4 | J4: =H4-F4 | K4: =E4-F4 | L4: =G4-H4 | M4: =IF(L4>K4,"YES - engine gap exceeds model",IF(L4=K4,"no - applied exactly once","no - applied LESS than once")) | N4: =IF(AND(I4=0,J4=0),"yes","NO")
A5: Cleric | B5: War Domain | C5: 6 | D5: 4 | E5: =SUMIFS('Per-spell working'!$H$2:$H$190,'Per-spell working'!$A$2:$A$190,"Cleric|War Domain",'Per-spell working'!$G$2:$G$190,"PAID") | F5: =SUMIFS('Per-spell working'!$I$2:$I$190,'Per-spell working'!$A$2:$A$190,"Cleric|War Domain",'Per-spell working'!$G$2:$G$190,"PAID") | G5: 8 | H5: 6 | I5: =G5-E5 | J5: =H5-F5 | K5: =E5-F5 | L5: =G5-H5 | M5: =IF(L5>K5,"YES - engine gap exceeds model",IF(L5=K5,"no - applied exactly once","no - applied LESS than once")) | N5: =IF(AND(I5=0,J5=0),"yes","NO")
A6: Druid | B6: Circle of the Land | C6: 4 | D6: 2 | E6: =SUMIFS('Per-spell working'!$H$2:$H$190,'Per-spell working'!$A$2:$A$190,"Druid|Circle of the Land",'Per-spell working'!$G$2:$G$190,"PAID") | F6: =SUMIFS('Per-spell working'!$I$2:$I$190,'Per-spell working'!$A$2:$A$190,"Druid|Circle of the Land",'Per-spell working'!$G$2:$G$190,"PAID") | G6: 8 | H6: 7 | I6: =G6-E6 | J6: =H6-F6 | K6: =E6-F6 | L6: =G6-H6 | M6: =IF(L6>K6,"YES - engine gap exceeds model",IF(L6=K6,"no - applied exactly once","no - applied LESS than once")) | N6: =IF(AND(I6=0,J6=0),"yes","NO")
A7: Druid | B7: Circle of the Moon | C7: 4 | D7: 2 | E7: =SUMIFS('Per-spell working'!$H$2:$H$190,'Per-spell working'!$A$2:$A$190,"Druid|Circle of the Moon",'Per-spell working'!$G$2:$G$190,"PAID") | F7: =SUMIFS('Per-spell working'!$I$2:$I$190,'Per-spell working'!$A$2:$A$190,"Druid|Circle of the Moon",'Per-spell working'!$G$2:$G$190,"PAID") | G7: 8 | H7: 7 | I7: =G7-E7 | J7: =H7-F7 | K7: =E7-F7 | L7: =G7-H7 | M7: =IF(L7>K7,"YES - engine gap exceeds model",IF(L7=K7,"no - applied exactly once","no - applied LESS than once")) | N7: =IF(AND(I7=0,J7=0),"yes","NO")
A8: Druid | B8: Circle of the Sea | C8: 7 | D8: 4 | E8: =SUMIFS('Per-spell working'!$H$2:$H$190,'Per-spell working'!$A$2:$A$190,"Druid|Circle of the Sea",'Per-spell working'!$G$2:$G$190,"PAID") | F8: =SUMIFS('Per-spell working'!$I$2:$I$190,'Per-spell working'!$A$2:$A$190,"Druid|Circle of the Sea",'Per-spell working'!$G$2:$G$190,"PAID") | G8: 11 | H8: 9 | I8: =G8-E8 | J8: =H8-F8 | K8: =E8-F8 | L8: =G8-H8 | M8: =IF(L8>K8,"YES - engine gap exceeds model",IF(L8=K8,"no - applied exactly once","no - applied LESS than once")) | N8: =IF(AND(I8=0,J8=0),"yes","NO")
A9: Druid | B9: Circle of the Stars | C9: 2 | D9: 0 | E9: =SUMIFS('Per-spell working'!$H$2:$H$190,'Per-spell working'!$A$2:$A$190,"Druid|Circle of the Stars",'Per-spell working'!$G$2:$G$190,"PAID") | F9: =SUMIFS('Per-spell working'!$I$2:$I$190,'Per-spell working'!$A$2:$A$190,"Druid|Circle of the Stars",'Per-spell working'!$G$2:$G$190,"PAID") | G9: 5 | H9: 5 | I9: =G9-E9 | J9: =H9-F9 | K9: =E9-F9 | L9: =G9-H9 | M9: =IF(L9>K9,"YES - engine gap exceeds model",IF(L9=K9,"no - applied exactly once","no - applied LESS than once")) | N9: =IF(AND(I9=0,J9=0),"yes","NO")
A10: Paladin | B10: Oath of Devotion | C10: 4 | D10: 6 | E10: =SUMIFS('Per-spell working'!$H$2:$H$190,'Per-spell working'!$A$2:$A$190,"Paladin|Oath of Devotion",'Per-spell working'!$G$2:$G$190,"PAID") | F10: =SUMIFS('Per-spell working'!$I$2:$I$190,'Per-spell working'!$A$2:$A$190,"Paladin|Oath of Devotion",'Per-spell working'!$G$2:$G$190,"PAID") | G10: 4 | H10: 4 | I10: =G10-E10 | J10: =H10-F10 | K10: =E10-F10 | L10: =G10-H10 | M10: =IF(L10>K10,"YES - engine gap exceeds model",IF(L10=K10,"no - applied exactly once","no - applied LESS than once")) | N10: =IF(AND(I10=0,J10=0),"yes","NO")
A11: Paladin | B11: Oath of Glory | C11: 4 | D11: 6 | E11: =SUMIFS('Per-spell working'!$H$2:$H$190,'Per-spell working'!$A$2:$A$190,"Paladin|Oath of Glory",'Per-spell working'!$G$2:$G$190,"PAID") | F11: =SUMIFS('Per-spell working'!$I$2:$I$190,'Per-spell working'!$A$2:$A$190,"Paladin|Oath of Glory",'Per-spell working'!$G$2:$G$190,"PAID") | G11: 4 | H11: 4 | I11: =G11-E11 | J11: =H11-F11 | K11: =E11-F11 | L11: =G11-H11 | M11: =IF(L11>K11,"YES - engine gap exceeds model",IF(L11=K11,"no - applied exactly once","no - applied LESS than once")) | N11: =IF(AND(I11=0,J11=0),"yes","NO")
A12: Paladin | B12: Oath of the Ancients | C12: 4 | D12: 6 | E12: =SUMIFS('Per-spell working'!$H$2:$H$190,'Per-spell working'!$A$2:$A$190,"Paladin|Oath of the Ancients",'Per-spell working'!$G$2:$G$190,"PAID") | F12: =SUMIFS('Per-spell working'!$I$2:$I$190,'Per-spell working'!$A$2:$A$190,"Paladin|Oath of the Ancients",'Per-spell working'!$G$2:$G$190,"PAID") | G12: 4 | H12: 4 | I12: =G12-E12 | J12: =H12-F12 | K12: =E12-F12 | L12: =G12-H12 | M12: =IF(L12>K12,"YES - engine gap exceeds model",IF(L12=K12,"no - applied exactly once","no - applied LESS than once")) | N12: =IF(AND(I12=0,J12=0),"yes","NO")
A13: Paladin | B13: Oath of Vengeance | C13: 4 | D13: 6 | E13: =SUMIFS('Per-spell working'!$H$2:$H$190,'Per-spell working'!$A$2:$A$190,"Paladin|Oath of Vengeance",'Per-spell working'!$G$2:$G$190,"PAID") | F13: =SUMIFS('Per-spell working'!$I$2:$I$190,'Per-spell working'!$A$2:$A$190,"Paladin|Oath of Vengeance",'Per-spell working'!$G$2:$G$190,"PAID") | G13: 4 | H13: 4 | I13: =G13-E13 | J13: =H13-F13 | K13: =E13-F13 | L13: =G13-H13 | M13: =IF(L13>K13,"YES - engine gap exceeds model",IF(L13=K13,"no - applied exactly once","no - applied LESS than once")) | N13: =IF(AND(I13=0,J13=0),"yes","NO")
A14: Ranger | B14: Fey Wanderer | C14: 2 | D14: 3 | E14: =SUMIFS('Per-spell working'!$H$2:$H$190,'Per-spell working'!$A$2:$A$190,"Ranger|Fey Wanderer",'Per-spell working'!$G$2:$G$190,"PAID") | F14: =SUMIFS('Per-spell working'!$I$2:$I$190,'Per-spell working'!$A$2:$A$190,"Ranger|Fey Wanderer",'Per-spell working'!$G$2:$G$190,"PAID") | G14: 2 | H14: 2 | I14: =G14-E14 | J14: =H14-F14 | K14: =E14-F14 | L14: =G14-H14 | M14: =IF(L14>K14,"YES - engine gap exceeds model",IF(L14=K14,"no - applied exactly once","no - applied LESS than once")) | N14: =IF(AND(I14=0,J14=0),"yes","NO")
A15: Ranger | B15: Gloom Stalker | C15: 2 | D15: 3 | E15: =SUMIFS('Per-spell working'!$H$2:$H$190,'Per-spell working'!$A$2:$A$190,"Ranger|Gloom Stalker",'Per-spell working'!$G$2:$G$190,"PAID") | F15: =SUMIFS('Per-spell working'!$I$2:$I$190,'Per-spell working'!$A$2:$A$190,"Ranger|Gloom Stalker",'Per-spell working'!$G$2:$G$190,"PAID") | G15: 2 | H15: 2 | I15: =G15-E15 | J15: =H15-F15 | K15: =E15-F15 | L15: =G15-H15 | M15: =IF(L15>K15,"YES - engine gap exceeds model",IF(L15=K15,"no - applied exactly once","no - applied LESS than once")) | N15: =IF(AND(I15=0,J15=0),"yes","NO")
A16: Sorcerer | B16: Aberrant Sorcery | C16: 7 | D16: 4 | E16: =SUMIFS('Per-spell working'!$H$2:$H$190,'Per-spell working'!$A$2:$A$190,"Sorcerer|Aberrant Sorcery",'Per-spell working'!$G$2:$G$190,"PAID") | F16: =SUMIFS('Per-spell working'!$I$2:$I$190,'Per-spell working'!$A$2:$A$190,"Sorcerer|Aberrant Sorcery",'Per-spell working'!$G$2:$G$190,"PAID") | G16: 12 | H16: 10 | I16: =G16-E16 | J16: =H16-F16 | K16: =E16-F16 | L16: =G16-H16 | M16: =IF(L16>K16,"YES - engine gap exceeds model",IF(L16=K16,"no - applied exactly once","no - applied LESS than once")) | N16: =IF(AND(I16=0,J16=0),"yes","NO")
A17: Sorcerer | B17: Clockwork Sorcery | C17: 6 | D17: 4 | E17: =SUMIFS('Per-spell working'!$H$2:$H$190,'Per-spell working'!$A$2:$A$190,"Sorcerer|Clockwork Sorcery",'Per-spell working'!$G$2:$G$190,"PAID") | F17: =SUMIFS('Per-spell working'!$I$2:$I$190,'Per-spell working'!$A$2:$A$190,"Sorcerer|Clockwork Sorcery",'Per-spell working'!$G$2:$G$190,"PAID") | G17: 8 | H17: 6 | I17: =G17-E17 | J17: =H17-F17 | K17: =E17-F17 | L17: =G17-H17 | M17: =IF(L17>K17,"YES - engine gap exceeds model",IF(L17=K17,"no - applied exactly once","no - applied LESS than once")) | N17: =IF(AND(I17=0,J17=0),"yes","NO")
A18: Sorcerer | B18: Draconic Sorcery | C18: 6 | D18: 4 | E18: =SUMIFS('Per-spell working'!$H$2:$H$190,'Per-spell working'!$A$2:$A$190,"Sorcerer|Draconic Sorcery",'Per-spell working'!$G$2:$G$190,"PAID") | F18: =SUMIFS('Per-spell working'!$I$2:$I$190,'Per-spell working'!$A$2:$A$190,"Sorcerer|Draconic Sorcery",'Per-spell working'!$G$2:$G$190,"PAID") | G18: 8 | H18: 6 | I18: =G18-E18 | J18: =H18-F18 | K18: =E18-F18 | L18: =G18-H18 | M18: =IF(L18>K18,"YES - engine gap exceeds model",IF(L18=K18,"no - applied exactly once","no - applied LESS than once")) | N18: =IF(AND(I18=0,J18=0),"yes","NO")
A19: Warlock | B19: Archfey Patron | C19: 7 | D19: 4 | E19: =SUMIFS('Per-spell working'!$H$2:$H$190,'Per-spell working'!$A$2:$A$190,"Warlock|Archfey Patron",'Per-spell working'!$G$2:$G$190,"PAID") | F19: =SUMIFS('Per-spell working'!$I$2:$I$190,'Per-spell working'!$A$2:$A$190,"Warlock|Archfey Patron",'Per-spell working'!$G$2:$G$190,"PAID") | G19: 9 | H19: 7 | I19: =G19-E19 | J19: =H19-F19 | K19: =E19-F19 | L19: =G19-H19 | M19: =IF(L19>K19,"YES - engine gap exceeds model",IF(L19=K19,"no - applied exactly once","no - applied LESS than once")) | N19: =IF(AND(I19=0,J19=0),"yes","NO")
A20: Warlock | B20: Celestial Patron | C20: 8 | D20: 4 | E20: =SUMIFS('Per-spell working'!$H$2:$H$190,'Per-spell working'!$A$2:$A$190,"Warlock|Celestial Patron",'Per-spell working'!$G$2:$G$190,"PAID") | F20: =SUMIFS('Per-spell working'!$I$2:$I$190,'Per-spell working'!$A$2:$A$190,"Warlock|Celestial Patron",'Per-spell working'!$G$2:$G$190,"PAID") | G20: 16 | H20: 14 | I20: =G20-E20 | J20: =H20-F20 | K20: =E20-F20 | L20: =G20-H20 | M20: =IF(L20>K20,"YES - engine gap exceeds model",IF(L20=K20,"no - applied exactly once","no - applied LESS than once")) | N20: =IF(AND(I20=0,J20=0),"yes","NO")
A21: Warlock | B21: Fiend Patron | C21: 6 | D21: 4 | E21: =SUMIFS('Per-spell working'!$H$2:$H$190,'Per-spell working'!$A$2:$A$190,"Warlock|Fiend Patron",'Per-spell working'!$G$2:$G$190,"PAID") | F21: =SUMIFS('Per-spell working'!$I$2:$I$190,'Per-spell working'!$A$2:$A$190,"Warlock|Fiend Patron",'Per-spell working'!$G$2:$G$190,"PAID") | G21: 8 | H21: 6 | I21: =G21-E21 | J21: =H21-F21 | K21: =E21-F21 | L21: =G21-H21 | M21: =IF(L21>K21,"YES - engine gap exceeds model",IF(L21=K21,"no - applied exactly once","no - applied LESS than once")) | N21: =IF(AND(I21=0,J21=0),"yes","NO")
A22: Warlock | B22: Great Old One Patron | C22: 6 | D22: 4 | E22: =SUMIFS('Per-spell working'!$H$2:$H$190,'Per-spell working'!$A$2:$A$190,"Warlock|Great Old One Patron",'Per-spell working'!$G$2:$G$190,"PAID") | F22: =SUMIFS('Per-spell working'!$I$2:$I$190,'Per-spell working'!$A$2:$A$190,"Warlock|Great Old One Patron",'Per-spell working'!$G$2:$G$190,"PAID") | G22: 8 | H22: 6 | I22: =G22-E22 | J22: =H22-F22 | K22: =E22-F22 | L22: =G22-H22 | M22: =IF(L22>K22,"YES - engine gap exceeds model",IF(L22=K22,"no - applied exactly once","no - applied LESS than once")) | N22: =IF(AND(I22=0,J22=0),"yes","NO")
A24: Subclasses of these classes that sell NO bundle - nothing to buy, no cost, no option
A25: Ranger | B25: Beast Master | G25: none | H25: none | M25: n/a - nothing to buy
A26: Ranger | B26: Hunter | G26: none | H26: none | M26: n/a - nothing to buy
A27: Sorcerer | B27: Wild Magic Sorcery | G27: none | H27: none | M27: n/a - nothing to buy
A29: Column M is the direct answer to 'is the origin discount applied twice?' - a doubled discount would make the ENGINE gap (L) exceed the model gap (K). It never does.

Sheet Price paths
A1: What the same buyer pays, by relationship to the class
A2: Verified by running compute(), not read off the source.
A4: Purchase | B4: Origin class | C4: Class unlocked, not origin | D4: Neither | E4: How that middle figure is reached
A5: Feature: Cleric: Blessed Strikes | B5: 10 | C5: 13 | D5: 17 | E5: sticker = cross - tier = 17 - 4 = 13
A6: Bundle: Cleric | Life Domain | B6: 6 | C6: 8 | D6: 8 | E6: no tier exists, so nothing is subtracted - it stays at cross = 8
A8: Column 3 of the guide's ability tables is the middle figure above and the bracket is the first - i.e.
A9: 'what a non-origin member of the class pays (what an origin member pays)'. Consistent in meaning.
A11: The real asymmetry: unlocking a class cuts 4 AP off that class's FEATURE (17 -> 13) but nothing off
A12: its BUNDLE (8 -> 8). Bundles have no sticker tier in the engine at all.
A14: As of DATA.version v0.347 a subclass purchase - ability or bundle - from a class you can neither
A15: build from nor have unlocked raises a blocking warning. Before that it was silently allowed, and
A16: because a bought bundle also claims that class's free subclass, no 15 AP unlock landed either.
A18: Neither table shows a discount applied twice. If it were, an Origin AP cell on the 'Per-spell
A19: working' sheet would fall below the 1 AP floor. None does.
